Workbook

Sheet raw_output
A1: age_effect | B1: initial_effect | C1: final_effect | D1: mort_effect | E1: prod_effect | F1: fert_effect | G1: pop_path_diffs | H1: pop_diffs_2045_2065 | I1: pop_diffs_2026_2100 | J1: total_pop_diff_2050 | K1: avg_diff | L1: avg_gdp_pc_diff | M1: discount_rate | N1: NPV | O1: QALY 20, $B | P1: QALY NPV, $T
A2: 40 | B2: 10 | C2: 20 | D2: 0.1 | E2: 0.6 | F2: 0 | G2: 6.5547806 | H2: 23.706732 | I2: 0.26811135 | J2: 0.2681277 | K2: 339.01455 | L2: 984.17306 | M2: 0.01 | N2: 25.967443 | O2: 53.133253 | P2: 3.1176538
A3: 40 | B3: 10 | C3: 20 | D3: 0.1 | E3: 0.6 | F3: 0 | G3: 6.5547806 | H3: 23.706732 | I3: 0.26811135 | J3: 0.2681277 | K3: 339.01455 | L3: 984.17306 | M3: 0.02 | N3: 14.427577 | O3: 53.133253 | P3: 1.8208154
A4: 40 | B4: 10 | C4: 20 | D4: 0.1 | E4: 0.6 | F4: 0 | G4: 6.5547806 | H4: 23.706732 | I4: 0.26811135 | J4: 0.2681277 | K4: 339.01455 | L4: 984.17306 | M4: 0.03 | N4: 8.4961746 | O4: 53.133253 | P4: 1.1190228
A5: 40 | B5: 10 | C5: 20 | D5: 0.1 | E5: 0.6 | F5: 0 | G5: 6.5547806 | H5: 23.706732 | I5: 0.26811135 | J5: 0.2681277 | K5: 339.01455 | L5: 984.17306 | M5: 0.035 | N5: 6.6541306 | O5: 53.133253 | P5: 0.89263237
A6: 40 | B6: 10 | C6: 20 | D6: 0.1 | E6: 0.6 | F6: 0 | G6: 6.5547806 | H6: 23.706732 | I6: 0.26811135 | J6: 0.2681277 | K6: 339.01455 | L6: 984.17306 | M6: 0.04 | N6: 5.2770644 | O6: 53.133253 | P6: 0.7195986
A7: 40 | B7: 10 | C7: 20 | D7: 0.1 | E7: 0.6 | F7: 0 | G7: 6.5547806 | H7: 23.706732 | I7: 0.26811135 | J7: 0.2681277 | K7: 339.01455 | L7: 984.17306 | M7: 0.05 | N7: 3.4327845 | O7: 53.133253 | P7: 0.48118842
A8: 40 | B8: 10 | C8: 20 | D8: 0.1 | E8: 0.6 | F8: 0 | G8: 6.5547806 | H8: 23.706732 | I8: 0.26811135 | J8: 0.2681277 | K8: 339.01455 | L8: 984.17306 | M8: 0.06 | N8: 2.3204045 | O8: 53.133253 | P8: 0.33258074
A9: 40 | B9: 10 | C9: 20 | D9: 0.1 | E9: 0.35 | F9: 0 | G9: 6.5547806 | H9: 23.706732 | I9: 0.26811135 | J9: 0.2681277 | K9: 201.2899 | L9: 507.82275 | M9: 0.01 | N9: 16.132365 | O9: 53.133253 | P9: 3.1176538
A10: 40 | B10: 10 | C10: 20 | D10: 0.1 | E10: 0.35 | F10: 0 | G10: 6.5547806 | H10: 23.706732 | I10: 0.26811135 | J10: 0.2681277 | K10: 201.2899 | L10: 507.82275 | M10: 0.02 | N10: 8.9055794 | O10: 53.133253 | P10: 1.8208154
A11: 40 | B11: 10 | C11: 20 | D11: 0.1 | E11: 0.35 | F11: 0 | G11: 6.5547806 | H11: 23.706732 | I11: 0.26811135 | J11: 0.2681277 | K11: 201.2899 | L11: 507.82275 | M11: 0.03 | N11: 5.2064902 | O11: 53.133253 | P11: 1.1190228
A12: 40 | B12: 10 | C12: 20 | D12: 0.1 | E12: 0.35 | F12: 0 | G12: 6.5547806 | H12: 23.706732 | I12: 0.26811135 | J12: 0.2681277 | K12: 201.2899 | L12: 507.82275 | M12: 0.035 | N12: 4.0621892 | O12: 53.133253 | P12: 0.89263237
A13: 40 | B13: 10 | C13: 20 | D13: 0.1 | E13: 0.35 | F13: 0 | G13: 6.5547806 | H13: 23.706732 | I13: 0.26811135 | J13: 0.2681277 | K13: 201.2899 | L13: 507.82275 | M13: 0.04 | N13: 3.209096 | O13: 53.133253 | P13: 0.7195986
... A197: 65 | B197: 10 | C197: 20 | D197: 2.5 | E197: 2.5 | F197: 0.6 | G197: 135.44598 | H197: 466.93838 | I197: 5.6236576 | J197: 5.6236576 | K197: 1696.7647 | L197: 1894.7362 | M197: 0.06 | N197: 11.372369 | O197: 1095.2527 | P197: 6.7178564

Sheet Overall Output. Labeled
J1: avg_diff | K1: NPV | L1: pop_diffs_2050 | M1: avg_gdp_pc_diff | N1: discount_rate | P1: mort_effect | Q1: prod_effect | R1: fert_effect | S1: initial_effect | T1: final_effect | U1: age_effect
A2: Chapter Number | B2: Future Number | C2: Future Name | D2: Simulation Number | E2: Table Number | F2: Mortality decrease in years | G2: Productivity increase in years | H2: Fertility increase in years | I2: Ages Affected | J2: Annual change in U.S. GDP (Avg. 2045-2064) | K2: NPV of increased GDP over several decades | L2: Additional Living People in 2050 | M2: Change in GDP Per Capita | N2: Discount Rate | O2: Adherence Rate | P2: adj mort | Q2: adj prod | R2: adj fert
A3: 5 | B3: 1 | C3: Slow brain aging | D3: 1 | E3: 1 | F3: 0.2 | G3: 0.7 | H3: 0 | I3: =CONCATENATE(U3,"+") -> 40+ | J3: =IF(V3>1000,_xlfn.CONCAT(TEXT(V3/1000,"$#.0"),"T"),_xlfn.CONCAT(TEXT(V3,"$#"),"B")) -> $201B | K3: =_xlfn.CONCAT(TEXT(SUMIFS(raw_output!$N$2:$N$197,raw_output!$M$2:$M$197,'Overall Output. Labeled'!$N3,raw_output!$A$2:$A$197,'Overall Output. Labeled'!$U3,raw_output!$B$2:$B$197,'Overall Output. Labeled'!$S3,raw_output!$C$2:$C$197,'Overall Output. Labeled'!$T3,raw_output!$D$2:$D$197,'Overall Output. Labeled'!$P3,raw_output!$E$2:$E$197,'Overall Output. Labeled'!$Q3,raw_output!$F$2:$F$197,'Overall Output. Labeled'!$R3),"$#.0"),"T") -> $8.9T | L3: =IF(W3>1000,_xlfn.CONCAT(TEXT(W3/1000,"#.#"),"M"),_xlfn.CONCAT(TEXT(W3,"#"),"k")) -> 268k | M3: =TEXT(SUMIFS(raw_output!$L$2:$L$197,raw_output!$M$2:$M$197,'Overall Output. Labeled'!$N3,raw_output!$A$2:$A$197,'Overall Output. Labeled'!$U3,raw_output!$B$2:$B$197,'Overall Output. Labeled'!$S3,raw_output!$C$2:$C$197,'Overall Output. Labeled'!$T3,raw_output!$D$2:$D$197,'Overall Output. Labeled'!$P3,raw_output!$E$2:$E$197,'Overall Output. Labeled'!$Q3,raw_output!$F$2:$F$197,'Overall Output. Labeled'!$R3),"$#.##") -> $507.82 | N3: 0.02 | O3: 0.5 | P3: =F3*$O3 -> 0.1 | Q3: =G3*$O3 -> 0.35 | R3: =H3*$O3 -> 0 | S3: 10 | T3: 20 | U3: 40 | V3: =SUMIFS(raw_output!$K$2:$K$197,raw_output!$A$2:$A$197,'Overall Output. Labeled'!$U3,raw_output!$B$2:$B$197,'Overall Output. Labeled'!$S3,raw_output!$C$2:$C$197,'Overall Output. Labeled'!$T3,raw_output!$D$2:$D$197,'Overall Output. Labeled'!$P3,raw_output!$E$2:$E$197,'Overall Output. Labeled'!$Q3,raw_output!$F$2:$F$197,'Overall Output. Labeled'!$R3,raw_output!$M$2:$M$197,'Overall Output. Labeled'!$N3) -> 201.2899 | W3: =SUMIFS(raw_output!$J$2:$J$197,raw_output!$M$2:$M$197,'Overall Output. Labeled'!$N3,raw_output!$A$2:$A$197,'Overall Output. Labeled'!$U3,raw_output!$B$2:$B$197,'Overall Output. Labeled'!$S3,raw_output!$C$2:$C$197,'Overall Output. Labeled'!$T3,raw_output!$D$2:$D$197,'Overall Output. Labeled'!$P3,raw_output!$E$2:$E$197,'Overall Output. Labeled'!$Q3,raw_output!$F$2:$F$197,'Overall Output. Labeled'!$R3)*1000 -> 268.1277
A4: 6 | B4: 2 | C4: Slow reproductive aging | D4: 3 | E4: 3 | F4: 0.02 | G4: 0.1 | H4: 1 | I4: =CONCATENATE(U4,"+") -> 40+ | J4: =IF(V4>1000,_xlfn.CONCAT(TEXT(V4/1000,"$#.0"),"T"),_xlfn.CONCAT(TEXT(V4,"$#"),"B")) -> $9B | K4: =_xlfn.CONCAT(TEXT(SUMIFS(raw_output!$N$2:$N$197,raw_output!$M$2:$M$197,'Overall Output. Labeled'!$N4,raw_output!$A$2:$A$197,'Overall Output. Labeled'!$U4,raw_output!$B$2:$B$197,'Overall Output. Labeled'!$S4,raw_output!$C$2:$C$197,'Overall Output. Labeled'!$T4,raw_output!$D$2:$D$197,'Overall Output. Labeled'!$P4,raw_output!$E$2:$E$197,'Overall Output. Labeled'!$Q4,raw_output!$F$2:$F$197,'Overall Output. Labeled'!$R4),"$#.0"),"T") -> $9.3T | L4: =IF(W4>1000,_xlfn.CONCAT(TEXT(W4/1000,"#.#"),"M"),_xlfn.CONCAT(TEXT(W4,"#"),"k")) -> 391k | M4: =TEXT(SUMIFS(raw_output!$L$2:$L$197,raw_output!$M$2:$M$197,'Overall Output. Labeled'!$N4,raw_output!$A$2:$A$197,'Overall Output. Labeled'!$U4,raw_output!$B$2:$B$197,'Overall Output. Labeled'!$S4,raw_output!$C$2:$C$197,'Overall Output. Labeled'!$T4,raw_output!$D$2:$D$197,'Overall Output. Labeled'!$P4,raw_output!$E$2:$E$197,'Overall Output. Labeled'!$Q4,raw_output!$F$2:$F$197,'Overall Output. Labeled'!$R4),"$#.##") -> -$5.25 | N4: 0.02 | O4: 0.5 | P4: =F4*$O4 -> 0.01 | Q4: =G4*$O4 -> 0.05 | R4: =H4*$O4 -> 0.5 | S4: 10 | T4: 20 | U4: 40 | V4: =SUMIFS(raw_output!$K$2:$K$197,raw_output!$A$2:$A$197,'Overall Output. Labeled'!$U4,raw_output!$B$2:$B$197,'Overall Output. Labeled'!$S4,raw_output!$C$2:$C$197,'Overall Output. Labeled'!$T4,raw_output!$D$2:$D$197,'Overall Output. Labeled'!$P4,raw_output!$E$2:$E$197,'Overall Output. Labeled'!$Q4,raw_output!$F$2:$F$197,'Overall Output. Labeled'!$R4,raw_output!$M$2:$M$197,'Overall Output. Labeled'!$N4) -> 9.0672976 | W4: {=SUMIFS(raw_output!$J$2:$J$197,raw_output!$M$2:$M$197,'Overall Output. Labeled'!$N4,raw_output!$A$2:$A$197,'Overall Output. Labeled'!$U4,raw_output!$B$2:$B$197,'Overall Output. Labeled'!$S4,raw_output!$C$2:$C$197,'Overall Output. Labeled'!$T4,raw_output!$D$2:$D$197,'Overall Output. Labeled'!$P4,raw_output!$E$2:$E$197,'Overall Output. Labeled'!$Q4,raw_output!$F$2:$F$197,'Overall Output. Labeled'!$R4)*1000} -> 391.36761
A5: 7 | B5: 3 | C5: Replacing aging, 4x | D5: 4 | E5: 4 | F5: 0.44 | G5: 0 | H5: 0 | I5: =CONCATENATE(U5,"+") -> 40+ | J5: =IF(V5>1000,_xlfn.CONCAT(TEXT(V5/1000,"$#.0"),"T"),_xlfn.CONCAT(TEXT(V5,"$#"),"B")) -> $118B | K5: =_xlfn.CONCAT(TEXT(SUMIFS(raw_output!$N$2:$N$197,raw_output!$M$2:$M$197,'Overall Output. Labeled'!$N5,raw_output!$A$2:$A$197,'Overall Output. Labeled'!$U5,raw_output!$B$2:$B$197,'Overall Output. Labeled'!$S5,raw_output!$C$2:$C$197,'Overall Output. Labeled'!$T5,raw_output!$D$2:$D$197,'Overall Output. Labeled'!$P5,raw_output!$E$2:$E$197,'Overall Output. Labeled'!$Q5,raw_output!$F$2:$F$197,'Overall Output. Labeled'!$R5),"$#.0"),"T") -> $6.8T | L5: =IF(W5>1000,_xlfn.CONCAT(TEXT(W5/1000,"#.#"),"M"),_xlfn.CONCAT(TEXT(W5,"#"),"k")) -> 1.2M | M5: =TEXT(SUMIFS(raw_output!$L$2:$L$197,raw_output!$M$2:$M$197,'Overall Output. Labeled'!$N5,raw_output!$A$2:$A$197,'Overall Output. Labeled'!$U5,raw_output!$B$2:$B$197,'Overall Output. Labeled'!$S5,raw_output!$C$2:$C$197,'Overall Output. Labeled'!$T5,raw_output!$D$2:$D$197,'Overall Output. Labeled'!$P5,raw_output!$E$2:$E$197,'Overall Output. Labeled'!$Q5,raw_output!$F$2:$F$197,'Overall Output. Labeled'!$R5),"$#.##") -> -$436.88 | N5: 0.02 | O5: 1 | P5: =F5*$O5 -> 0.44 | Q5: =G5*$O5 -> 0 | R5: =H5*$O5 -> 0 | S5: 10 | T5: 20 | U5: 40 | V5: =SUMIFS(raw_output!$K$2:$K$197,raw_output!$A$2:$A$197,'Overall Output. Labeled'!$U5,raw_output!$B$2:$B$197,'Overall Output. Labeled'!$S5,raw_output!$C$2:$C$197,'Overall Output. Labeled'!$T5,raw_output!$D$2:$D$197,'Overall Output. Labeled'!$P5,raw_output!$E$2:$E$197,'Overall Output. Labeled'!$Q5,raw_output!$F$2:$F$197,'Overall Output. Labeled'!$R5,raw_output!$M$2:$M$197,'Overall Output. Labeled'!$N5) -> 118.19972 | W5: {=SUMIFS(raw_output!$J$2:$J$197,raw_output!$M$2:$M$197,'Overall Output. Labeled'!$N5,raw_output!$A$2:$A$197,'Overall Output. Labeled'!$U5,raw_output!$B$2:$B$197,'Overall Output. Labeled'!$S5,raw_output!$C$2:$C$197,'Overall Output. Labeled'!$T5,raw_output!$D$2:$D$197,'Overall Output. Labeled'!$P5,raw_output!$E$2:$E$197,'Overall Output. Labeled'!$Q5,raw_output!$F$2:$F$197,'Overall Output. Labeled'!$R5)*1000} -> 1193.1255
A6: 7 | B6: 3 | C6: Replacing aging, 2x | D6: 4 | E6: 4 | F6: 0.22 | G6: 0 | H6: 0 | I6: =CONCATENATE(U6,"+") -> 40+ | J6: =IF(V6>1000,_xlfn.CONCAT(TEXT(V6/1000,"$#.0"),"T"),_xlfn.CONCAT(TEXT(V6,"$#"),"B")) -> $50B | K6: =_xlfn.CONCAT(TEXT(SUMIFS(raw_output!$N$2:$N$197,raw_output!$M$2:$M$197,'Overall Output. Labeled'!$N6,raw_output!$A$2:$A$197,'Overall Output. Labeled'!$U6,raw_output!$B$2:$B$197,'Overall Output. Labeled'!$S6,raw_output!$C$2:$C$197,'Overall Output. Labeled'!$T6,raw_output!$D$2:$D$197,'Overall Output. Labeled'!$P6,raw_output!$E$2:$E$197,'Overall Output. Labeled'!$Q6,raw_output!$F$2:$F$197,'Overall Output. Labeled'!$R6),"$#.0"),"T") -> $3.2T | L6: =IF(W6>1000,_xlfn.CONCAT(TEXT(W6/1000,"#.#"),"M"),_xlfn.CONCAT(TEXT(W6,"#"),"k")) -> 592k | M6: =TEXT(SUMIFS(raw_output!$L$2:$L$197,raw_output!$M$2:$M$197,'Overall Output. Labeled'!$N6,raw_output!$A$2:$A$197,'Overall Output. Labeled'!$U6,raw_output!$B$2:$B$197,'Overall Output. Labeled'!$S6,raw_output!$C$2:$C$197,'Overall Output. Labeled'!$T6,raw_output!$D$2:$D$197,'Overall Output. Labeled'!$P6,raw_output!$E$2:$E$197,'Overall Output. Labeled'!$Q6,raw_output!$F$2:$F$197,'Overall Output. Labeled'!$R6),"$#.##") -> -$247.15 | N6: 0.02 | O6: 1 | P6: =F6*$O6 -> 0.22 | Q6: =G6*$O6 -> 0 | R6: =H6*$O6 -> 0 | S6: 10 | T6: 20 | U6: 40 | V6: =SUMIFS(raw_output!$K$2:$K$197,raw_output!$A$2:$A$197,'Overall Output. Labeled'!$U6,raw_output!$B$2:$B$197,'Overall Output. Labeled'!$S6,raw_output!$C$2:$C$197,'Overall Output. Labeled'!$T6,raw_output!$D$2:$D$197,'Overall Output. Labeled'!$P6,raw_output!$E$2:$E$197,'Overall Output. Labeled'!$Q6,raw_output!$F$2:$F$197,'Overall Output. Labeled'!$R6,raw_output!$M$2:$M$197,'Overall Output. Labeled'!$N6) -> 49.515117 | W6: {=SUMIFS(raw_output!$J$2:$J$197,raw_output!$M$2:$M$197,'Overall Output. Labeled'!$N6,raw_output!$A$2:$A$197,'Overall Output. Labeled'!$U6,raw_output!$B$2:$B$197,'Overall Output. Labeled'!$S6,raw_output!$C$2:$C$197,'Overall Output. Labeled'!$T6,raw_output!$D$2:$D$197,'Overall Output. Labeled'!$P6,raw_output!$E$2:$E$197,'Overall Output. Labeled'!$Q6,raw_output!$F$2:$F$197,'Overall Output. Labeled'!$R6)*1000} -> 592.2211
A7: 8 | B7: 4 | C7: 1st gen | D7: ? | F7: 0.82 | G7: 0.727 | H7: 0 | I7: =CONCATENATE(U7,"+") -> 65+ | J7: =IF(V7>1000,_xlfn.CONCAT(TEXT(V7/1000,"$#.0"),"T"),_xlfn.CONCAT(TEXT(V7,"$#"),"B")) -> $40B | K7: =_xlfn.CONCAT(TEXT(SUMIFS(raw_output!$N$2:$N$197,raw_output!$M$2:$M$197,'Overall Output. Labeled'!$N7,raw_output!$A$2:$A$197,'Overall Output. Labeled'!$U7,raw_output!$B$2:$B$197,'Overall Output. Labeled'!$S7,raw_output!$C$2:$C$197,'Overall Output. Labeled'!$T7,raw_output!$D$2:$D$197,'Overall Output. Labeled'!$P7,raw_output!$E$2:$E$197,'Overall Output. Labeled'!$Q7,raw_output!$F$2:$F$197,'Overall Output. Labeled'!$R7),"$#.0"),"T") -> $2.4T | L7: =IF(W7>1000,_xlfn.CONCAT(TEXT(W7/1000,"#.#"),"M"),_xlfn.CONCAT(TEXT(W7,"#"),"k")) -> 275k | M7: =TEXT(SUMIFS(raw_output!$L$2:$L$197,raw_output!$M$2:$M$197,'Overall Output. Labeled'!$N7,raw_output!$A$2:$A$197,'Overall Output. Labeled'!$U7,raw_output!$B$2:$B$197,'Overall Output. Labeled'!$S7,raw_output!$C$2:$C$197,'Overall Output. Labeled'!$T7,raw_output!$D$2:$D$197,'Overall Output. Labeled'!$P7,raw_output!$E$2:$E$197,'Overall Output. Labeled'!$Q7,raw_output!$F$2:$F$197,'Overall Output. Labeled'!$R7),"$#.##") -> -$19.85 | N7: 0.02 | O7: 0.11 | P7: 0.09 | Q7: 0.08 | R7: =H7*$O7 -> 0 | S7: 5 | T7: 10 | U7: 65 | V7: =SUMIFS(raw_output!$K$2:$K$197,raw_output!$A$2:$A$197,'Overall Output. Labeled'!$U7,raw_output!$B$2:$B$197,'Overall Output. Labeled'!$S7,raw_output!$C$2:$C$197,'Overall Output. Labeled'!$T7,raw_output!$D$2:$D$197,'Overall Output. Labeled'!$P7,raw_output!$E$2:$E$197,'Overall Output. Labeled'!$Q7,raw_output!$F$2:$F$197,'Overall Output. Labeled'!$R7,raw_output!$M$2:$M$197,'Overall Output. Labeled'!$N7) -> 40.442704 | W7: {=SUMIFS(raw_output!$J$2:$J$197,raw_output!$M$2:$M$197,'Overall Output. Labeled'!$N7,raw_output!$A$2:$A$197,'Overall Output. Labeled'!$U7,raw_output!$B$2:$B$197,'Overall Output. Labeled'!$S7,raw_output!$C$2:$C$197,'Overall Output. Labeled'!$T7,raw_output!$D$2:$D$197,'Overall Output. Labeled'!$P7,raw_output!$E$2:$E$197,'Overall Output. Labeled'!$Q7,raw_output!$F$2:$F$197,'Overall Output. Labeled'!$R7)*1000} -> 275.20844
C8: 1st gen, broader population | F8: 0.81 | G8: 0.72 | H8: 0 | I8: =CONCATENATE(U8,"+") -> 65+ | J8: =IF(V8>1000,_xlfn.CONCAT(TEXT(V8/1000,"$#.0"),"T"),_xlfn.CONCAT(TEXT(V8,"$#"),"B")) -> $79B | K8: =_xlfn.CONCAT(TEXT(SUMIFS(raw_output!$N$2:$N$197,raw_output!$M$2:$M$197,'Overall Output. Labeled'!$N8,raw_output!$A$2:$A$197,'Overall Output. Labeled'!$U8,raw_output!$B$2:$B$197,'Overall Output. Labeled'!$S8,raw_output!$C$2:$C$197,'Overall Output. Labeled'!$T8,raw_output!$D$2:$D$197,'Overall Output. Labeled'!$P8,raw_output!$E$2:$E$197,'Overall Output. Labeled'!$Q8,raw_output!$F$2:$F$197,'Overall Output. Labeled'!$R8),"$#.0"),"T") -> $4.2T | L8: =IF(W8>1000,_xlfn.CONCAT(TEXT(W8/1000,"#.#"),"M"),_xlfn.CONCAT(TEXT(W8,"#"),"k")) -> 460k | M8: =TEXT(SUMIFS(raw_output!$L$2:$L$197,raw_output!$M$2:$M$197,'Overall Output. Labeled'!$N8,raw_output!$A$2:$A$197,'Overall Output. Labeled'!$U8,raw_output!$B$2:$B$197,'Overall Output. Labeled'!$S8,raw_output!$C$2:$C$197,'Overall Output. Labeled'!$T8,raw_output!$D$2:$D$197,'Overall Output. Labeled'!$P8,raw_output!$E$2:$E$197,'Overall Output. Labeled'!$Q8,raw_output!$F$2:$F$197,'Overall Output. Labeled'!$R8),"$#.##") -> $3.94 | N8: 0.02 | O8: 0.185 | P8: 0.15 | Q8: 0.13 | R8: 0 | S8: 5 | T8: 10 | U8: 65 | V8: =SUMIFS(raw_output!$K$2:$K$197,raw_output!$A$2:$A$197,'Overall Output. Labeled'!$U8,raw_output!$B$2:$B$197,'Overall Output. Labeled'!$S8,raw_output!$C$2:$C$197,'Overall Output. Labeled'!$T8,raw_output!$D$2:$D$197,'Overall Output. Labeled'!$P8,raw_output!$E$2:$E$197,'Overall Output. Labeled'!$Q8,raw_output!$F$2:$F$197,'Overall Output. Labeled'!$R8,raw_output!$M$2:$M$197,'Overall Output. Labeled'!$N8) -> 78.713204 | W8: {=SUMIFS(raw_output!$J$2:$J$197,raw_output!$M$2:$M$197,'Overall Output. Labeled'!$N8,raw_output!$A$2:$A$197,'Overall Output. Labeled'!$U8,raw_output!$B$2:$B$197,'Overall Output. Labeled'!$S8,raw_output!$C$2:$C$197,'Overall Output. Labeled'!$T8,raw_output!$D$2:$D$197,'Overall Output. Labeled'!$P8,raw_output!$E$2:$E$197,'Overall Output. Labeled'!$Q8,raw_output!$F$2:$F$197,'Overall Output. Labeled'!$R8)*1000} -> 460.1928
A9: 8 | B9: 4 | C9: 2nd gen | D9: ? | E9: ? | F9: 0.82 | G9: 1.44 | I9: =CONCATENATE(U9,"+") -> 40+ | J9: =IF(V9>1000,_xlfn.CONCAT(TEXT(V9/1000,"$#.0"),"T"),_xlfn.CONCAT(TEXT(V9,"$#"),"B")) -> $505B | K9: =_xlfn.CONCAT(TEXT(SUMIFS(raw_output!$N$2:$N$197,raw_output!$M$2:$M$197,'Overall Output. Labeled'!$N9,raw_output!$A$2:$A$197,'Overall Output. Labeled'!$U9,raw_output!$B$2:$B$197,'Overall Output. Labeled'!$S9,raw_output!$C$2:$C$197,'Overall Output. Labeled'!$T9,raw_output!$D$2:$D$197,'Overall Output. Labeled'!$P9,raw_output!$E$2:$E$197,'Overall Output. Labeled'!$Q9,raw_output!$F$2:$F$197,'Overall Output. Labeled'!$R9),"$#.0"),"T") -> $22.2T | L9: =IF(W9>1000,_xlfn.CONCAT(TEXT(W9/1000,"#.#"),"M"),_xlfn.CONCAT(TEXT(W9,"#"),"k")) -> 1.1M | M9: =TEXT(SUMIFS(raw_output!$L$2:$L$197,raw_output!$M$2:$M$197,'Overall Output. Labeled'!$N9,raw_output!$A$2:$A$197,'Overall Output. Labeled'!$U9,raw_output!$B$2:$B$197,'Overall Output. Labeled'!$S9,raw_output!$C$2:$C$197,'Overall Output. Labeled'!$T9,raw_output!$D$2:$D$197,'Overall Output. Labeled'!$P9,raw_output!$E$2:$E$197,'Overall Output. Labeled'!$Q9,raw_output!$F$2:$F$197,'Overall Output. Labeled'!$R9),"$#.##") -> $954.97 | N9: 0.02 | O9: 0.5 | P9: =F9*$O9 -> 0.41 | Q9: =G9*$O9 -> 0.72 | R9: =H9*$O9 -> 0 | S9: 10 | T9: 20 | U9: 40 | V9: =SUMIFS(raw_output!$K$2:$K$197,raw_output!$A$2:$A$197,'Overall Output. Labeled'!$U9,raw_output!$B$2:$B$197,'Overall Output. Labeled'!$S9,raw_output!$C$2:$C$197,'Overall Output. Labeled'!$T9,raw_output!$D$2:$D$197,'Overall Output. Labeled'!$P9,raw_output!$E$2:$E$197,'Overall Output. Labeled'!$Q9,raw_output!$F$2:$F$197,'Overall Output. Labeled'!$R9,raw_output!$M$2:$M$197,'Overall Output. Labeled'!$N9) -> 505.03884 | W9: {=SUMIFS(raw_output!$J$2:$J$197,raw_output!$M$2:$M$197,'Overall Output. Labeled'!$N9,raw_output!$A$2:$A$197,'Overall Output. Labeled'!$U9,raw_output!$B$2:$B$197,'Overall Output. Labeled'!$S9,raw_output!$C$2:$C$197,'Overall Output. Labeled'!$T9,raw_output!$D$2:$D$197,'Overall Output. Labeled'!$P9,raw_output!$E$2:$E$197,'Overall Output. Labeled'!$Q9,raw_output!$F$2:$F$197,'Overall Output. Labeled'!$R9)*1000} -> 1110.6654
C10: Delta, 2nd gen - 1st gen | J10: =IF(V10>1000,_xlfn.CONCAT(TEXT(V10/1000,"$#.0"),"T"),_xlfn.CONCAT(TEXT(V10,"$#"),"B")) -> $426B | K10: $36.2T | L10: =IF(W10>1000,_xlfn.CONCAT(TEXT(W10/1000,"#.#"),"M"),_xlfn.CONCAT(TEXT(W10,"#"),"k")) -> 650k | V10: =V9-V8 -> 426.32563 | W10: =W9-W8 -> 650.47256
A11: 8 | B11: 4 | C11: 2nd gen + OOC | D11: ? | E11: ? | F11: 0.82 | G11: 1.44 | I11: =CONCATENATE(U11,"+") -> 40+ | J11: =IF(V11>1000,_xlfn.CONCAT(TEXT(V11/1000,"$#.0"),"T"),_xlfn.CONCAT(TEXT(V11,"$#"),"B")) -> $523B | K11: =_xlfn.CONCAT(TEXT(SUMIFS(raw_output!$N$2:$N$197,raw_output!$M$2:$M$197,'Overall Output. Labeled'!$N11,raw_output!$A$2:$A$197,'Overall Output. Labeled'!$U11,raw_output!$B$2:$B$197,'Overall Output. Labeled'!$S11,raw_output!$C$2:$C$197,'Overall Output. Labeled'!$T11,raw_output!$D$2:$D$197,'Overall Output. Labeled'!$P11,raw_output!$E$2:$E$197,'Overall Output. Labeled'!$Q11,raw_output!$F$2:$F$197,'Overall Output. Labeled'!$R11),"$#.0"),"T") -> $23.3T | L11: =IF(W11>1000,_xlfn.CONCAT(TEXT(W11/1000,"#.#"),"M"),_xlfn.CONCAT(TEXT(W11,"#"),"k")) -> 1.3M | M11: =TEXT(SUMIFS(raw_output!$L$2:$L$197,raw_output!$M$2:$M$197,'Overall Output. Labeled'!$N11,raw_output!$A$2:$A$197,'Overall Output. Labeled'!$U11,raw_output!$B$2:$B$197,'Overall Output. Labeled'!$S11,raw_output!$C$2:$C$197,'Overall Output. Labeled'!$T11,raw_output!$D$2:$D$197,'Overall Output. Labeled'!$P11,raw_output!$E$2:$E$197,'Overall Output. Labeled'!$Q11,raw_output!$F$2:$F$197,'Overall Output. Labeled'!$R11),"$#.##") -> $936.43 | N11: 0.02 | O11: 0.5 | P11: =F11*$O11 -> 0.41 | Q11: =G11*$O11 -> 0.72 | R11: =H11*$O11 -> 0 | S11: 8 | T11: 16 | U11: 40 | V11: =SUMIFS(raw_output!$K$2:$K$197,raw_output!$A$2:$A$197,'Overall Output. Labeled'!$U11,raw_output!$B$2:$B$197,'Overall Output. Labeled'!$S11,raw_output!$C$2:$C$197,'Overall Output. Labeled'!$T11,raw_output!$D$2:$D$197,'Overall Output. Labeled'!$P11,raw_output!$E$2:$E$197,'Overall Output. Labeled'!$Q11,raw_output!$F$2:$F$197,'Overall Output. Labeled'!$R11,raw_output!$M$2:$M$197,'Overall Output. Labeled'!$N11) -> 522.61023 | W11: {=SUMIFS(raw_output!$J$2:$J$197,raw_output!$M$2:$M$197,'Overall Output. Labeled'!$N11,raw_output!$A$2:$A$197,'Overall Output. Labeled'!$U11,raw_output!$B$2:$B$197,'Overall Output. Labeled'!$S11,raw_output!$C$2:$C$197,'Overall Output. Labeled'!$T11,raw_output!$D$2:$D$197,'Overall Output. Labeled'!$P11,raw_output!$E$2:$E$197,'Overall Output. Labeled'!$Q11,raw_output!$F$2:$F$197,'Overall Output. Labeled'!$R11)*1000} -> 1331.7213
C12: Delta, 2nd gen OOC - 2nd gen | J12: $18B | K12: $2.0T | L12: =IF(W12>1000,_xlfn.CONCAT(TEXT(W12/1000,"#.#"),"M"),_xlfn.CONCAT(TEXT(W12,"#"),"k")) -> 221k | V12: =V11-V9 -> 17.57139 | W12: =W11-W9 -> 221.05593
A13: 9 | B13: 5 | C13: 41 the new 40 | D13: 5 | E13: ? | F13: 1 | G13: 1 | H13: 1 | I13: =CONCATENATE(U13,"+") -> 40+ | J13: =IF(V13>1000,_xlfn.CONCAT(TEXT(V13/1000,"$#.0"),"T"),_xlfn.CONCAT(TEXT(V13,"$#"),"B")) -> $408B | K13: =_xlfn.CONCAT(TEXT(SUMIFS(raw_output!$N$2:$N$197,raw_output!$M$2:$M$197,'Overall Output. Labeled'!$N13,raw_output!$A$2:$A$197,'Overall Output. Labeled'!$U13,raw_output!$B$2:$B$197,'Overall Output. Labeled'!$S13,raw_output!$C$2:$C$197,'Overall Output. Labeled'!$T13,raw_output!$D$2:$D$197,'Overall Output. Labeled'!$P13,raw_output!$E$2:$E$197,'Overall Output. Labeled'!$Q13,raw_output!$F$2:$F$197,'Overall Output. Labeled'!$R13),"$#.0"),"T") -> $27.1T | L13: =IF(W13>1000,_xlfn.CONCAT(TEXT(W13/1000,"#.#"),"M"),_xlfn.CONCAT(TEXT(W13,"#"),"k")) -> 1.7M | M13: =TEXT(SUMIFS(raw_output!$L$2:$L$197,raw_output!$M$2:$M$197,'Overall Output. Labeled'!$N13,raw_output!$A$2:$A$197,'Overall Output. Labeled'!$U13,raw_output!$B$2:$B$197,'Overall Output. Labeled'!$S13,raw_output!$C$2:$C$197,'Overall Output. Labeled'!$T13,raw_output!$D$2:$D$197,'Overall Output. Labeled'!$P13,raw_output!$E$2:$E$197,'Overall Output. Labeled'!$Q13,raw_output!$F$2:$F$197,'Overall Output. Labeled'!$R13),"$#.##") -> $425.39 | N13: 0.02 | O13: 0.5 | P13: =F13*$O13 -> 0.5 | Q13: =G13*$O13 -> 0.5 | R13: =H13*$O13 -> 0.5 | S13: 10 | T13: 20 | U13: 40 | V13: =SUMIFS(raw_output!$K$2:$K$197,raw_output!$A$2:$A$197,'Overall Output. Labeled'!$U13,raw_output!$B$2:$B$197,'Overall Output. Labeled'!$S13,raw_output!$C$2:$C$197,'Overall Output. Labeled'!$T13,raw_output!$D$2:$D$197,'Overall Output. Labeled'!$P13,raw_output!$E$2:$E$197,'Overall Output. Labeled'!$Q13,raw_output!$F$2:$F$197,'Overall Output. Labeled'!$R13,raw_output!$M$2:$M$197,'Overall Output. Labeled'!$N13) -> 408.38262 | W13: {=SUMIFS(raw_output!$J$2:$J$197,raw_output!$M$2:$M$197,'Overall Output. Labeled'!$N13,raw_output!$A$2:$A$197,'Overall Output. Labeled'!$U13,raw_output!$B$2:$B$197,'Overall Output. Labeled'!$S13,raw_output!$C$2:$C$197,'Overall Output. Labeled'!$T13,raw_output!$D$2:$D$197,'Overall Output. Labeled'!$P13,raw_output!$E$2:$E$197,'Overall Output. Labeled'!$Q13,raw_output!$F$2:$F$197,'Overall Output. Labeled'!$R13)*1000} -> 1723.1995
A14: 9 | B14: 5 | C14: 41 the new 40 | D14: 5+ | E14: ? | F14: 1 | G14: 1 | H14: 1 | I14: =CONCATENATE(U14,"+") -> 65+ | J14: =IF(V14>1000,_xlfn.CONCAT(TEXT(V14/1000,"$#.0"),"T"),_xlfn.CONCAT(TEXT(V14,"$#"),"B")) -> $326B | K14: =_xlfn.CONCAT(TEXT(SUMIFS(raw_output!$N$2:$N$197,raw_output!$M$2:$M$197,'Overall Output. Labeled'!$N14,raw_output!$A$2:$A$197,'Overall Output. Labeled'!$U14,raw_output!$B$2:$B$197,'Overall Output. Labeled'!$S14,raw_output!$C$2:$C$197,'Overall Output. Labeled'!$T14,raw_output!$D$2:$D$197,'Overall Output. Labeled'!$P14,raw_output!$E$2:$E$197,'Overall Output. Labeled'!$Q14,raw_output!$F$2:$F$197,'Overall Output. Labeled'!$R14),"$#.0"),"T") -> $14.3T | L14: =IF(W14>1000,_xlfn.CONCAT(TEXT(W14/1000,"#.#"),"M"),_xlfn.CONCAT(TEXT(W14,"#"),"k")) -> 1.2M | M14: =TEXT(SUMIFS(raw_output!$L$2:$L$197,raw_output!$M$2:$M$197,'Overall Output. Labeled'!$N14,raw_output!$A$2:$A$197,'Overall Output. Labeled'!$U14,raw_output!$B$2:$B$197,'Overall Output. Labeled'!$S14,raw_output!$C$2:$C$197,'Overall Output. Labeled'!$T14,raw_output!$D$2:$D$197,'Overall Output. Labeled'!$P14,raw_output!$E$2:$E$197,'Overall Output. Labeled'!$Q14,raw_output!$F$2:$F$197,'Overall Output. Labeled'!$R14),"$#.##") -> $327.93 | N14: 0.02 | O14: 0.5 | P14: =F14*$O14 -> 0.5 | Q14: =G14*$O14 -> 0.5 | R14: =H14*$O14 -> 0.5 | S14: 10 | T14: 20 | U14: 65 | V14: =SUMIFS(raw_output!$K$2:$K$197,raw_output!$A$2:$A$197,'Overall Output. Labeled'!$U14,raw_output!$B$2:$B$197,'Overall Output. Labeled'!$S14,raw_output!$C$2:$C$197,'Overall Output. Labeled'!$T14,raw_output!$D$2:$D$197,'Overall Output. Labeled'!$P14,raw_output!$E$2:$E$197,'Overall Output. Labeled'!$Q14,raw_output!$F$2:$F$197,'Overall Output. Labeled'!$R14,raw_output!$M$2:$M$197,'Overall Output. Labeled'!$N14) -> 326.36233 | W14: {=SUMIFS(raw_output!$J$2:$J$197,raw_output!$M$2:$M$197,'Overall Output. Labeled'!$N14,raw_output!$A$2:$A$197,'Overall Output. Labeled'!$U14,raw_output!$B$2:$B$197,'Overall Output. Labeled'!$S14,raw_output!$C$2:$C$197,'Overall Output. Labeled'!$T14,raw_output!$D$2:$D$197,'Overall Output. Labeled'!$P14,raw_output!$E$2:$E$197,'Overall Output. Labeled'!$Q14,raw_output!$F$2:$F$197,'Overall Output. Labeled'!$R14)*1000} -> 1178.3827
A15: 9 | B15: 5 | C15: 45 the new 40 | D15: 5+ | E15: ? | F15: 5 | G15: 5 | H15: 5 | I15: =CONCATENATE(U15,"+") -> 40+ | J15: =IF(V15>1000,_xlfn.CONCAT(TEXT(V15/1000,"$#.0"),"T"),_xlfn.CONCAT(TEXT(V15,"$#"),"B")) -> $2.0T | K15: =_xlfn.CONCAT(TEXT(SUMIFS(raw_output!$N$2:$N$197,raw_output!$M$2:$M$197,'Overall Output. Labeled'!$N15,raw_output!$A$2:$A$197,'Overall Output. Labeled'!$U15,raw_output!$B$2:$B$197,'Overall Output. Labeled'!$S15,raw_output!$C$2:$C$197,'Overall Output. Labeled'!$T15,raw_output!$D$2:$D$197,'Overall Output. Labeled'!$P15,raw_output!$E$2:$E$197,'Overall Output. Labeled'!$Q15,raw_output!$F$2:$F$197,'Overall Output. Labeled'!$R15),"$#.0"),"T") -> $101.9T | L15: =IF(W15>1000,_xlfn.CONCAT(TEXT(W15/1000,"#.#"),"M"),_xlfn.CONCAT(TEXT(W15,"#"),"k")) -> 6.9M | M15: =TEXT(SUMIFS(raw_output!$L$2:$L$197,raw_output!$M$2:$M$197,'Overall Output. Labeled'!$N15,raw_output!$A$2:$A$197,'Overall Output. Labeled'!$U15,raw_output!$B$2:$B$197,'Overall Output. Labeled'!$S15,raw_output!$C$2:$C$197,'Overall Output. Labeled'!$T15,raw_output!$D$2:$D$197,'Overall Output. Labeled'!$P15,raw_output!$E$2:$E$197,'Overall Output. Labeled'!$Q15,raw_output!$F$2:$F$197,'Overall Output. Labeled'!$R15),"$#.##") -> $2211.12 | N15: 0.02 | O15: 0.5 | P15: =F15*$O15 -> 2.5 | Q15: =G15*$O15 -> 2.5 | R15: 0.6 | S15: 10 | T15: 20 | U15: 40 | V15: =SUMIFS(raw_output!$K$2:$K$197,raw_output!$A$2:$A$197,'Overall Output. Labeled'!$U15,raw_output!$B$2:$B$197,'Overall Output. Labeled'!$S15,raw_output!$C$2:$C$197,'Overall Output. Labeled'!$T15,raw_output!$D$2:$D$197,'Overall Output. Labeled'!$P15,raw_output!$E$2:$E$197,'Overall Output. Labeled'!$Q15,raw_output!$F$2:$F$197,'Overall Output. Labeled'!$R15,raw_output!$M$2:$M$197,'Overall Output. Labeled'!$N15) -> 2027.9728 | W15: {=SUMIFS(raw_output!$J$2:$J$197,raw_output!$M$2:$M$197,'Overall Output. Labeled'!$N15,raw_output!$A$2:$A$197,'Overall Output. Labeled'!$U15,raw_output!$B$2:$B$197,'Overall Output. Labeled'!$S15,raw_output!$C$2:$C$197,'Overall Output. Labeled'!$T15,raw_output!$D$2:$D$197,'Overall Output. Labeled'!$P15,raw_output!$E$2:$E$197,'Overall Output. Labeled'!$Q15,raw_output!$F$2:$F$197,'Overall Output. Labeled'!$R15)*1000} -> 6911.1497
A16: 9 | B16: 5 | C16: 45 the new 40 | D16: 5+ | E16: ? | F16: 5 | G16: 5 | H16: 5 | I16: =CONCATENATE(U16,"+") -> 65+ | J16: =IF(V16>1000,_xlfn.CONCAT(TEXT(V16/1000,"$#.0"),"T"),_xlfn.CONCAT(TEXT(V16,"$#"),"B")) -> $1.7T | K16: =_xlfn.CONCAT(TEXT(SUMIFS(raw_output!$N$2:$N$197,raw_output!$M$2:$M$197,'Overall Output. Labeled'!$N16,raw_output!$A$2:$A$197,'Overall Output. Labeled'!$U16,raw_output!$B$2:$B$197,'Overall Output. Labeled'!$S16,raw_output!$C$2:$C$197,'Overall Output. Labeled'!$T16,raw_output!$D$2:$D$197,'Overall Output. Labeled'!$P16,raw_output!$E$2:$E$197,'Overall Output. Labeled'!$Q16,raw_output!$F$2:$F$197,'Overall Output. Labeled'!$R16),"$#.0"),"T") -> $72.8T | L16: =IF(W16>1000,_xlfn.CONCAT(TEXT(W16/1000,"#.#"),"M"),_xlfn.CONCAT(TEXT(W16,"#"),"k")) -> 5.6M | M16: =TEXT(SUMIFS(raw_output!$L$2:$L$197,raw_output!$M$2:$M$197,'Overall Output. Labeled'!$N16,raw_output!$A$2:$A$197,'Overall Output. Labeled'!$U16,raw_output!$B$2:$B$197,'Overall Output. Labeled'!$S16,raw_output!$C$2:$C$197,'Overall Output. Labeled'!$T16,raw_output!$D$2:$D$197,'Overall Output. Labeled'!$P16,raw_output!$E$2:$E$197,'Overall Output. Labeled'!$Q16,raw_output!$F$2:$F$197,'Overall Output. Labeled'!$R16),"$#.##") -> $1894.74 | N16: 0.02 | O16: 0.5 | P16: =F16*$O16 -> 2.5 | Q16: =G16*$O16 -> 2.5 | R16: 0.6 | S16: 10 | T16: 20 | U16: 65 | V16: =SUMIFS(raw_output!$K$2:$K$197,raw_output!$A$2:$A$197,'Overall Output. Labeled'!$U16,raw_output!$B$2:$B$197,'Overall Output. Labeled'!$S16,raw_output!$C$2:$C$197,'Overall Output. Labeled'!$T16,raw_output!$D$2:$D$197,'Overall Output. Labeled'!$P16,raw_output!$E$2:$E$197,'Overall Output. Labeled'!$Q16,raw_output!$F$2:$F$197,'Overall Output. Labeled'!$R16,raw_output!$M$2:$M$197,'Overall Output. Labeled'!$N16) -> 1696.7647 | W16: {=SUMIFS(raw_output!$J$2:$J$197,raw_output!$M$2:$M$197,'Overall Output. Labeled'!$N16,raw_output!$A$2:$A$197,'Overall Output. Labeled'!$U16,raw_output!$B$2:$B$197,'Overall Output. Labeled'!$S16,raw_output!$C$2:$C$197,'Overall Output. Labeled'!$T16,raw_output!$D$2:$D$197,'Overall Output. Labeled'!$P16,raw_output!$E$2:$E$197,'Overall Output. Labeled'!$Q16,raw_output!$F$2:$F$197,'Overall Output. Labeled'!$R16)*1000} -> 5623.6576
A17: 11 | B17: NA | C17: Curing all cancers | E17: ? | F17: ? | G17: 0 | H17: 0 | I17: =CONCATENATE(U17,"+") -> 40+ | K17: $80T | N17: 0.035 | S17: 10 | T17: 20 | U17: 40 | V17: =SUMIFS(raw_output!$K$2:$K$197,raw_output!$A$2:$A$197,'Overall Output. Labeled'!$U17,raw_output!$B$2:$B$197,'Overall Output. Labeled'!$S17,raw_output!$C$2:$C$197,'Overall Output. Labeled'!$T17,raw_output!$D$2:$D$197,'Overall Output. Labeled'!$P17,raw_output!$E$2:$E$197,'Overall Output. Labeled'!$Q17,raw_output!$F$2:$F$197,'Overall Output. Labeled'!$R17,raw_output!$M$2:$M$197,'Overall Output. Labeled'!$N17) -> 0
A18: 11 | B18: NA | C18: 45 the new 40, 100% adhere | D18: 5+ | E18: ? | F18: 5 | G18: 5 | H18: 5 | I18: =CONCATENATE(U18,"+") -> 40+ | J18: =IF(V18>1000,_xlfn.CONCAT(TEXT(V18/1000,"$#.0"),"T"),_xlfn.CONCAT(TEXT(V18,"$#"),"B")) -> $4.0T | K18: =_xlfn.CONCAT(TEXT(SUMIFS(raw_output!$N$2:$N$197,raw_output!$M$2:$M$197,'Overall Output. Labeled'!$N18,raw_output!$A$2:$A$197,'Overall Output. Labeled'!$U18,raw_output!$B$2:$B$197,'Overall Output. Labeled'!$S18,raw_output!$C$2:$C$197,'Overall Output. Labeled'!$T18,raw_output!$D$2:$D$197,'Overall Output. Labeled'!$P18,raw_output!$E$2:$E$197,'Overall Output. Labeled'!$Q18,raw_output!$F$2:$F$197,'Overall Output. Labeled'!$R18),"$#.0"),"T") -> $83.6T | L18: =IF(W18>1000,_xlfn.CONCAT(TEXT(W18/1000,"#.#"),"M"),_xlfn.CONCAT(TEXT(W18,"#"),"k")) -> 12.9M | M18: =TEXT(SUMIFS(raw_output!$L$2:$L$197,raw_output!$M$2:$M$197,'Overall Output. Labeled'!$N18,raw_output!$A$2:$A$197,'Overall Output. Labeled'!$U18,raw_output!$B$2:$B$197,'Overall Output. Labeled'!$S18,raw_output!$C$2:$C$197,'Overall Output. Labeled'!$T18,raw_output!$D$2:$D$197,'Overall Output. Labeled'!$P18,raw_output!$E$2:$E$197,'Overall Output. Labeled'!$Q18,raw_output!$F$2:$F$197,'Overall Output. Labeled'!$R18),"$#.##") -> $4048.2 | N18: 0.035 | O18: 1 | P18: =F18*$O18 -> 5 | Q18: =G18*$O18 -> 5 | R18: 0.6 | S18: 10 | T18: 20 | U18: 40 | V18: =SUMIFS(raw_output!$K$2:$K$197,raw_output!$A$2:$A$197,'Overall Output. Labeled'!$U18,raw_output!$B$2:$B$197,'Overall Output. Labeled'!$S18,raw_output!$C$2:$C$197,'Overall Output. Labeled'!$T18,raw_output!$D$2:$D$197,'Overall Output. Labeled'!$P18,raw_output!$E$2:$E$197,'Overall Output. Labeled'!$Q18,raw_output!$F$2:$F$197,'Overall Output. Labeled'!$R18,raw_output!$M$2:$M$197,'Overall Output. Labeled'!$N18) -> 3951.0771 | W18: {=SUMIFS(raw_output!$J$2:$J$197,raw_output!$M$2:$M$197,'Overall Output. Labeled'!$N18,raw_output!$A$2:$A$197,'Overall Output. Labeled'!$U18,raw_output!$B$2:$B$197,'Overall Output. Labeled'!$S18,raw_output!$C$2:$C$197,'Overall Output. Labeled'!$T18,raw_output!$D$2:$D$197,'Overall Output. Labeled'!$P18,raw_output!$E$2:$E$197,'Overall Output. Labeled'!$Q18,raw_output!$F$2:$F$197,'Overall Output. Labeled'!$R18)*1000} -> 12900.835
A19: 11 | B19: NA | C19: Deploying existing Malaria vaccines | F19: NA | G19: NA | H19: NA | I19: NA | K19: $36.0T | N19: 0.02 | O19: 1 | S19: 10 | T19: 20 | U19: NA | V19: =SUMIFS(raw_output!$K$2:$K$197,raw_output!$A$2:$A$197,'Overall Output. Labeled'!$U19,raw_output!$B$2:$B$197,'Overall Output. Labeled'!$S19,raw_output!$C$2:$C$197,'Overall Output. Labeled'!$T19,raw_output!$D$2:$D$197,'Overall Output. Labeled'!$P19,raw_output!$E$2:$E$197,'Overall Output. Labeled'!$Q19,raw_output!$F$2:$F$197,'Overall Output. Labeled'!$R19,raw_output!$M$2:$M$197,'Overall Output. Labeled'!$N19) -> 0
A20: 11 | B20: NA | C20: Regular exercise | F20: 2.52 | G20: 1.26 | H20: 0 | I20: =CONCATENATE(U20,"+") -> 40+ | J20: =IF(V20>1000,_xlfn.CONCAT(TEXT(V20/1000,"$#.0"),"T"),_xlfn.CONCAT(TEXT(V20,"$#"),"B")) -> $715B | K20: =_xlfn.CONCAT(TEXT(SUMIFS(raw_output!$N$2:$N$197,raw_output!$M$2:$M$197,'Overall Output. Labeled'!$N20,raw_output!$A$2:$A$197,'Overall Output. Labeled'!$U20,raw_output!$B$2:$B$197,'Overall Output. Labeled'!$S20,raw_output!$C$2:$C$197,'Overall Output. Labeled'!$T20,raw_output!$D$2:$D$197,'Overall Output. Labeled'!$P20,raw_output!$E$2:$E$197,'Overall Output. Labeled'!$Q20,raw_output!$F$2:$F$197,'Overall Output. Labeled'!$R20),"$#.0"),"T") -> $38.4T | L20: =IF(W20>1000,_xlfn.CONCAT(TEXT(W20/1000,"#.#"),"M"),_xlfn.CONCAT(TEXT(W20,"#"),"k")) -> 6.5M | M20: =TEXT(SUMIFS(raw_output!$L$2:$L$197,raw_output!$M$2:$M$197,'Overall Output. Labeled'!$N20,raw_output!$A$2:$A$197,'Overall Output. Labeled'!$U20,raw_output!$B$2:$B$197,'Overall Output. Labeled'!$S20,raw_output!$C$2:$C$197,'Overall Output. Labeled'!$T20,raw_output!$D$2:$D$197,'Overall Output. Labeled'!$P20,raw_output!$E$2:$E$197,'Overall Output. Labeled'!$Q20,raw_output!$F$2:$F$197,'Overall Output. Labeled'!$R20),"$#.##") -> -$2229.5 | N20: 0.02 | O20: 1 | P20: =F20*$O20 -> 2.52 | Q20: 0 | R20: 0 | S20: 10 | T20: 20 | U20: 40 | V20: =SUMIFS(raw_output!$K$2:$K$197,raw_output!$A$2:$A$197,'Overall Output. Labeled'!$U20,raw_output!$B$2:$B$197,'Overall Output. Labeled'!$S20,raw_output!$C$2:$C$197,'Overall Output. Labeled'!$T20,raw_output!$D$2:$D$197,'Overall Output. Labeled'!$P20,raw_output!$E$2:$E$197,'Overall Output. Labeled'!$Q20,raw_output!$F$2:$F$197,'Overall Output. Labeled'!$R20,raw_output!$M$2:$M$197,'Overall Output. Labeled'!$N20) -> 714.84514 | W20: {=SUMIFS(raw_output!$J$2:$J$197,raw_output!$M$2:$M$197,'Overall Output. Labeled'!$N20,raw_output!$A$2:$A$197,'Overall Output. Labeled'!$U20,raw_output!$B$2:$B$197,'Overall Output. Labeled'!$S20,raw_output!$C$2:$C$197,'Overall Output. Labeled'!$T20,raw_output!$D$2:$D$197,'Overall Output. Labeled'!$P20,raw_output!$E$2:$E$197,'Overall Output. Labeled'!$Q20,raw_output!$F$2:$F$197,'Overall Output. Labeled'!$R20)*1000} -> 6529.4667
A21: 12 | B21: NA | C21: 41 the new 40, 100% adhere | F21: 1 | G21: 1 | H21: 1 | I21: =CONCATENATE(U21,"+") -> 40+ | J21: =IF(V21>1000,_xlfn.CONCAT(TEXT(V21/1000,"$#.0"),"T"),_xlfn.CONCAT(TEXT(V21,"$#"),"B")) -> $857B | K21: =_xlfn.CONCAT(TEXT(SUMIFS(raw_output!$N$2:$N$197,raw_output!$M$2:$M$197,'Overall Output. Labeled'!$N21,raw_output!$A$2:$A$197,'Overall Output. Labeled'!$U21,raw_output!$B$2:$B$197,'Overall Output. Labeled'!$S21,raw_output!$C$2:$C$197,'Overall Output. Labeled'!$T21,raw_output!$D$2:$D$197,'Overall Output. Labeled'!$P21,raw_output!$E$2:$E$197,'Overall Output. Labeled'!$Q21,raw_output!$F$2:$F$197,'Overall Output. Labeled'!$R21),"$#.0"),"T") -> $47.1T | L21: =IF(W21>1000,_xlfn.CONCAT(TEXT(W21/1000,"#.#"),"M"),_xlfn.CONCAT(TEXT(W21,"#"),"k")) -> 3.1M | M21: =TEXT(SUMIFS(raw_output!$L$2:$L$197,raw_output!$M$2:$M$197,'Overall Output. Labeled'!$N21,raw_output!$A$2:$A$197,'Overall Output. Labeled'!$U21,raw_output!$B$2:$B$197,'Overall Output. Labeled'!$S21,raw_output!$C$2:$C$197,'Overall Output. Labeled'!$T21,raw_output!$D$2:$D$197,'Overall Output. Labeled'!$P21,raw_output!$E$2:$E$197,'Overall Output. Labeled'!$Q21,raw_output!$F$2:$F$197,'Overall Output. Labeled'!$R21),"$#.##") -> $957.09 | N21: 0.02 | O21: 1 | P21: =F21*$O21 -> 1 | Q21: =G21*$O21 -> 1 | R21: 0.5 | S21: 10 | T21: 20 | U21: 40 | V21: =SUMIFS(raw_output!$K$2:$K$197,raw_output!$A$2:$A$197,'Overall Output. Labeled'!$U21,raw_output!$B$2:$B$197,'Overall Output. Labeled'!$S21,raw_output!$C$2:$C$197,'Overall Output. Labeled'!$T21,raw_output!$D$2:$D$197,'Overall Output. Labeled'!$P21,raw_output!$E$2:$E$197,'Overall Output. Labeled'!$Q21,raw_output!$F$2:$F$197,'Overall Output. Labeled'!$R21,raw_output!$M$2:$M$197,'Overall Output. Labeled'!$N21) -> 857.09418 | W21: {=SUMIFS(raw_output!$J$2:$J$197,raw_output!$M$2:$M$197,'Overall Output. Labeled'!$N21,raw_output!$A$2:$A$197,'Overall Output. Labeled'!$U21,raw_output!$B$2:$B$197,'Overall Output. Labeled'!$S21,raw_output!$C$2:$C$197,'Overall Output. Labeled'!$T21,raw_output!$D$2:$D$197,'Overall Output. Labeled'!$P21,raw_output!$E$2:$E$197,'Overall Output. Labeled'!$Q21,raw_output!$F$2:$F$197,'Overall Output. Labeled'!$R21)*1000} -> 3127.9637
A22: 12 | C22: 41 is the new 40, Scott et al | F22: 1 | G22: 1 | H22: 1 | I22: NA | K22: $46.8T | N22: 0.02 | S22: 10 | T22: 20 | U22: NA | V22: =SUMIFS(raw_output!$K$2:$K$197,raw_output!$A$2:$A$197,'Overall Output. Labeled'!$U22,raw_output!$B$2:$B$197,'Overall Output. Labeled'!$S22,raw_output!$C$2:$C$197,'Overall Output. Labeled'!$T22,raw_output!$D$2:$D$197,'Overall Output. Labeled'!$P22,raw_output!$E$2:$E$197,'Overall Output. Labeled'!$Q22,raw_output!$F$2:$F$197,'Overall Output. Labeled'!$R22,raw_output!$M$2:$M$197,'Overall Output. Labeled'!$N22) -> 0
A23: 12 | C23: 41 the new 40, 100% adhere, QALY | F23: 1 | G23: 1 | H23: 1 | I23: =CONCATENATE(U23,"+") -> 40+ | J23: =IF(V23>1000,_xlfn.CONCAT(TEXT(V23/1000,"$#.0"),"T"),_xlfn.CONCAT(TEXT(V23,"$#"),"B")) -> $857B | K23: =_xlfn.CONCAT(TEXT(SUMIFS(raw_output!$P$2:$P$197,raw_output!$M$2:$M$197,'Overall Output. Labeled'!$N21,raw_output!$A$2:$A$197,'Overall Output. Labeled'!$U21,raw_output!$B$2:$B$197,'Overall Output. Labeled'!$S21,raw_output!$C$2:$C$197,'Overall Output. Labeled'!$T21,raw_output!$D$2:$D$197,'Overall Output. Labeled'!$P21,raw_output!$E$2:$E$197,'Overall Output. Labeled'!$Q21,raw_output!$F$2:$F$197,'Overall Output. Labeled'!$R21),"$#.0"),"T") -> $28.4T | L23: =IF(W23>1000,_xlfn.CONCAT(TEXT(W23/1000,"#.#"),"M"),_xlfn.CONCAT(TEXT(W23,"#"),"k")) -> 3.1M | M23: =TEXT(SUMIFS(raw_output!$L$2:$L$197,raw_output!$M$2:$M$197,'Overall Output. Labeled'!$N23,raw_output!$A$2:$A$197,'Overall Output. Labeled'!$U23,raw_output!$B$2:$B$197,'Overall Output. Labeled'!$S23,raw_output!$C$2:$C$197,'Overall Output. Labeled'!$T23,raw_output!$D$2:$D$197,'Overall Output. Labeled'!$P23,raw_output!$E$2:$E$197,'Overall Output. Labeled'!$Q23,raw_output!$F$2:$F$197,'Overall Output. Labeled'!$R23),"$#.##") -> $957.09 | N23: 0.02 | O23: 1 | P23: =F23*$O23 -> 1 | Q23: =G23*$O23 -> 1 | R23: 0.5 | S23: 10 | T23: 20 | U23: 40 | V23: =SUMIFS(raw_output!$K$2:$K$197,raw_output!$A$2:$A$197,'Overall Output. Labeled'!$U23,raw_output!$B$2:$B$197,'Overall Output. Labeled'!$S23,raw_output!$C$2:$C$197,'Overall Output. Labeled'!$T23,raw_output!$D$2:$D$197,'Overall Output. Labeled'!$P23,raw_output!$E$2:$E$197,'Overall Output. Labeled'!$Q23,raw_output!$F$2:$F$197,'Overall Output. Labeled'!$R23,raw_output!$M$2:$M$197,'Overall Output. Labeled'!$N23) -> 857.09418 | W23: {=SUMIFS(raw_output!$J$2:$J$197,raw_output!$M$2:$M$197,'Overall Output. Labeled'!$N23,raw_output!$A$2:$A$197,'Overall Output. Labeled'!$U23,raw_output!$B$2:$B$197,'Overall Output. Labeled'!$S23,raw_output!$C$2:$C$197,'Overall Output. Labeled'!$T23,raw_output!$D$2:$D$197,'Overall Output. Labeled'!$P23,raw_output!$E$2:$E$197,'Overall Output. Labeled'!$Q23,raw_output!$F$2:$F$197,'Overall Output. Labeled'!$R23)*1000} -> 3127.9637
A24: Appendix | C24: 1 yr shift in mortality | F24: 1 | G24: 0 | H24: 0 | I24: =CONCATENATE(U24,"+") -> 40+ | J24: =IF(V24>1000,_xlfn.CONCAT(TEXT(V24/1000,"$#.0"),"T"),_xlfn.CONCAT(TEXT(V24,"$#"),"B")) -> $137B | K24: =_xlfn.CONCAT(TEXT(SUMIFS(raw_output!$N$2:$N$197,raw_output!$M$2:$M$197,'Overall Output. Labeled'!$N24,raw_output!$A$2:$A$197,'Overall Output. Labeled'!$U24,raw_output!$B$2:$B$197,'Overall Output. Labeled'!$S24,raw_output!$C$2:$C$197,'Overall Output. Labeled'!$T24,raw_output!$D$2:$D$197,'Overall Output. Labeled'!$P24,raw_output!$E$2:$E$197,'Overall Output. Labeled'!$Q24,raw_output!$F$2:$F$197,'Overall Output. Labeled'!$R24),"$#.0"),"T") -> $7.8T | L24: =IF(W24>1000,_xlfn.CONCAT(TEXT(W24/1000,"#.#"),"M"),_xlfn.CONCAT(TEXT(W24,"#"),"k")) -> 1.4M | M24: =TEXT(SUMIFS(raw_output!$L$2:$L$197,raw_output!$M$2:$M$197,'Overall Output. Labeled'!$N24,raw_output!$A$2:$A$197,'Overall Output. Labeled'!$U24,raw_output!$B$2:$B$197,'Overall Output. Labeled'!$S24,raw_output!$C$2:$C$197,'Overall Output. Labeled'!$T24,raw_output!$D$2:$D$197,'Overall Output. Labeled'!$P24,raw_output!$E$2:$E$197,'Overall Output. Labeled'!$Q24,raw_output!$F$2:$F$197,'Overall Output. Labeled'!$R24),"$#.##") -> -$489.4 | N24: 0.02 | O24: 0.5 | P24: =F24*$O24 -> 0.5 | Q24: =G24*$O24 -> 0 | R24: =H24*$O24 -> 0 | S24: 10 | T24: 20 | U24: 40 | V24: =SUMIFS(raw_output!$K$2:$K$197,raw_output!$A$2:$A$197,'Overall Output. Labeled'!$U24,raw_output!$B$2:$B$197,'Overall Output. Labeled'!$S24,raw_output!$C$2:$C$197,'Overall Output. Labeled'!$T24,raw_output!$D$2:$D$197,'Overall Output. Labeled'!$P24,raw_output!$E$2:$E$197,'Overall Output. Labeled'!$Q24,raw_output!$F$2:$F$197,'Overall Output. Labeled'!$R24,raw_output!$M$2:$M$197,'Overall Output. Labeled'!$N24) -> 137.08382 | W24: {=SUMIFS(raw_output!$J$2:$J$197,raw_output!$M$2:$M$197,'Overall Output. Labeled'!$N24,raw_output!$A$2:$A$197,'Overall Output. Labeled'!$U24,raw_output!$B$2:$B$197,'Overall Output. Labeled'!$S24,raw_output!$C$2:$C$197,'Overall Output. Labeled'!$T24,raw_output!$D$2:$D$197,'Overall Output. Labeled'!$P24,raw_output!$E$2:$E$197,'Overall Output. Labeled'!$Q24,raw_output!$F$2:$F$197,'Overall Output. Labeled'!$R24)*1000} -> 1358.5421
A25: Appendix | C25: 1 year shift in productivity | F25: 0 | G25: 1 | H25: 0 | I25: =CONCATENATE(U25,"+") -> 40+ | J25: =IF(V25>1000,_xlfn.CONCAT(TEXT(V25/1000,"$#.0"),"T"),_xlfn.CONCAT(TEXT(V25,"$#"),"B")) -> $252B | K25: =_xlfn.CONCAT(TEXT(SUMIFS(raw_output!$N$2:$N$197,raw_output!$M$2:$M$197,'Overall Output. Labeled'!$N25,raw_output!$A$2:$A$197,'Overall Output. Labeled'!$U25,raw_output!$B$2:$B$197,'Overall Output. Labeled'!$S25,raw_output!$C$2:$C$197,'Overall Output. Labeled'!$T25,raw_output!$D$2:$D$197,'Overall Output. Labeled'!$P25,raw_output!$E$2:$E$197,'Overall Output. Labeled'!$Q25,raw_output!$F$2:$F$197,'Overall Output. Labeled'!$R25),"$#.0"),"T") -> $10.6T | L25: =IF(W25>1000,_xlfn.CONCAT(TEXT(W25/1000,"#.#"),"M"),_xlfn.CONCAT(TEXT(W25,"#"),"k")) -> k | M25: =TEXT(SUMIFS(raw_output!$L$2:$L$197,raw_output!$M$2:$M$197,'Overall Output. Labeled'!$N25,raw_output!$A$2:$A$197,'Overall Output. Labeled'!$U25,raw_output!$B$2:$B$197,'Overall Output. Labeled'!$S25,raw_output!$C$2:$C$197,'Overall Output. Labeled'!$T25,raw_output!$D$2:$D$197,'Overall Output. Labeled'!$P25,raw_output!$E$2:$E$197,'Overall Output. Labeled'!$Q25,raw_output!$F$2:$F$197,'Overall Output. Labeled'!$R25),"$#.##") -> $875.24 | N25: 0.02 | O25: 0.5 | P25: =F25*$O25 -> 0 | Q25: =G25*$O25 -> 0.5 | R25: =H25*$O25 -> 0 | S25: 10 | T25: 20 | U25: 40 | V25: =SUMIFS(raw_output!$K$2:$K$197,raw_output!$A$2:$A$197,'Overall Output. Labeled'!$U25,raw_output!$B$2:$B$197,'Overall Output. Labeled'!$S25,raw_output!$C$2:$C$197,'Overall Output. Labeled'!$T25,raw_output!$D$2:$D$197,'Overall Output. Labeled'!$P25,raw_output!$E$2:$E$197,'Overall Output. Labeled'!$Q25,raw_output!$F$2:$F$197,'Overall Output. Labeled'!$R25,raw_output!$M$2:$M$197,'Overall Output. Labeled'!$N25) -> 252.27253 | W25: {=SUMIFS(raw_output!$J$2:$J$197,raw_output!$M$2:$M$197,'Overall Output. Labeled'!$N25,raw_output!$A$2:$A$197,'Overall Output. Labeled'!$U25,raw_output!$B$2:$B$197,'Overall Output. Labeled'!$S25,raw_output!$C$2:$C$197,'Overall Output. Labeled'!$T25,raw_output!$D$2:$D$197,'Overall Output. Labeled'!$P25,raw_output!$E$2:$E$197,'Overall Output. Labeled'!$Q25,raw_output!$F$2:$F$197,'Overall Output. Labeled'!$R25)*1000} -> 0
A26: Appendix | C26: 1 year shift in fertility | F26: 0 | G26: 0 | H26: 1 | I26: =CONCATENATE(U26,"+") -> 40+ | J26: =IF(V26>1000,_xlfn.CONCAT(TEXT(V26/1000,"$#.0"),"T"),_xlfn.CONCAT(TEXT(V26,"$#"),"B")) -> -$21B | K26: =_xlfn.CONCAT(TEXT(SUMIFS(raw_output!$N$2:$N$197,raw_output!$M$2:$M$197,'Overall Output. Labeled'!$N26,raw_output!$A$2:$A$197,'Overall Output. Labeled'!$U26,raw_output!$B$2:$B$197,'Overall Output. Labeled'!$S26,raw_output!$C$2:$C$197,'Overall Output. Labeled'!$T26,raw_output!$D$2:$D$197,'Overall Output. Labeled'!$P26,raw_output!$E$2:$E$197,'Overall Output. Labeled'!$Q26,raw_output!$F$2:$F$197,'Overall Output. Labeled'!$R26),"$#.0"),"T") -> $8.0T | L26: =IF(W26>1000,_xlfn.CONCAT(TEXT(W26/1000,"#.#"),"M"),_xlfn.CONCAT(TEXT(W26,"#"),"k")) -> 365k | M26: =TEXT(SUMIFS(raw_output!$L$2:$L$197,raw_output!$M$2:$M$197,'Overall Output. Labeled'!$N26,raw_output!$A$2:$A$197,'Overall Output. Labeled'!$U26,raw_output!$B$2:$B$197,'Overall Output. Labeled'!$S26,raw_output!$C$2:$C$197,'Overall Output. Labeled'!$T26,raw_output!$D$2:$D$197,'Overall Output. Labeled'!$P26,raw_output!$E$2:$E$197,'Overall Output. Labeled'!$Q26,raw_output!$F$2:$F$197,'Overall Output. Labeled'!$R26),"$#.##") -> -$89.29 | N26: 0.02 | O26: 0.5 | P26: =F26*$O26 -> 0 | Q26: =G26*$O26 -> 0 | R26: =H26*$O26 -> 0.5 | S26: 10 | T26: 20 | U26: 40 | V26: =SUMIFS(raw_output!$K$2:$K$197,raw_output!$A$2:$A$197,'Overall Output. Labeled'!$U26,raw_output!$B$2:$B$197,'Overall Output. Labeled'!$S26,raw_output!$C$2:$C$197,'Overall Output. Labeled'!$T26,raw_output!$D$2:$D$197,'Overall Output. Labeled'!$P26,raw_output!$E$2:$E$197,'Overall Output. Labeled'!$Q26,raw_output!$F$2:$F$197,'Overall Output. Labeled'!$R26,raw_output!$M$2:$M$197,'Overall Output. Labeled'!$N26) -> -20.679367 | W26: {=SUMIFS(raw_output!$J$2:$J$197,raw_output!$M$2:$M$197,'Overall Output. Labeled'!$N26,raw_output!$A$2:$A$197,'Overall Output. Labeled'!$U26,raw_output!$B$2:$B$197,'Overall Output. Labeled'!$S26,raw_output!$C$2:$C$197,'Overall Output. Labeled'!$T26,raw_output!$D$2:$D$197,'Overall Output. Labeled'!$P26,raw_output!$E$2:$E$197,'Overall Output. Labeled'!$Q26,raw_output!$F$2:$F$197,'Overall Output. Labeled'!$R26)*1000} -> 364.63356
A27: Appendix | C27: 1% decrease in mortality | I27: =CONCATENATE(U27,"+") -> 40+ | J27: =IF(V27>1000,_xlfn.CONCAT(TEXT(V27/1000,"$#.0"),"T"),_xlfn.CONCAT(TEXT(V27,"$#"),"B")) -> $22B | K27: =_xlfn.CONCAT(TEXT(SUMIFS(raw_output!$N$2:$N$197,raw_output!$M$2:$M$197,'Overall Output. Labeled'!$N27,raw_output!$A$2:$A$197,'Overall Output. Labeled'!$U27,raw_output!$B$2:$B$197,'Overall Output. Labeled'!$S27,raw_output!$C$2:$C$197,'Overall Output. Labeled'!$T27,raw_output!$D$2:$D$197,'Overall Output. Labeled'!$P27,raw_output!$E$2:$E$197,'Overall Output. Labeled'!$Q27,raw_output!$F$2:$F$197,'Overall Output. Labeled'!$R27),"$#.0"),"T") -> $1.8T | L27: =IF(W27>1000,_xlfn.CONCAT(TEXT(W27/1000,"#.#"),"M"),_xlfn.CONCAT(TEXT(W27,"#"),"k")) -> 349k | M27: =TEXT(SUMIFS(raw_output!$L$2:$L$197,raw_output!$M$2:$M$197,'Overall Output. Labeled'!$N27,raw_output!$A$2:$A$197,'Overall Output. Labeled'!$U27,raw_output!$B$2:$B$197,'Overall Output. Labeled'!$S27,raw_output!$C$2:$C$197,'Overall Output. Labeled'!$T27,raw_output!$D$2:$D$197,'Overall Output. Labeled'!$P27,raw_output!$E$2:$E$197,'Overall Output. Labeled'!$Q27,raw_output!$F$2:$F$197,'Overall Output. Labeled'!$R27),"$#.##") -> -$170.95 | N27: 0.02 | O27: 1 | P27: 0.13 | Q27: =G27 -> 0 | R27: =H27 -> 0 | S27: 10 | T27: 20 | U27: 40 | V27: =SUMIFS(raw_output!$K$2:$K$197,raw_output!$A$2:$A$197,'Overall Output. Labeled'!$U27,raw_output!$B$2:$B$197,'Overall Output. Labeled'!$S27,raw_output!$C$2:$C$197,'Overall Output. Labeled'!$T27,raw_output!$D$2:$D$197,'Overall Output. Labeled'!$P27,raw_output!$E$2:$E$197,'Overall Output. Labeled'!$Q27,raw_output!$F$2:$F$197,'Overall Output. Labeled'!$R27,raw_output!$M$2:$M$197,'Overall Output. Labeled'!$N27) -> 21.61646 | W27: {=SUMIFS(raw_output!$J$2:$J$197,raw_output!$M$2:$M$197,'Overall Output. Labeled'!$N27,raw_output!$A$2:$A$197,'Overall Output. Labeled'!$U27,raw_output!$B$2:$B$197,'Overall Output. Labeled'!$S27,raw_output!$C$2:$C$197,'Overall Output. Labeled'!$T27,raw_output!$D$2:$D$197,'Overall Output. Labeled'!$P27,raw_output!$E$2:$E$197,'Overall Output. Labeled'!$Q27,raw_output!$F$2:$F$197,'Overall Output. Labeled'!$R27)*1000} -> 348.91063
A28: Appendix | C28: 1% increase in productivity | I28: =CONCATENATE(U28,"+") -> 40+ | J28: =IF(V28>1000,_xlfn.CONCAT(TEXT(V28/1000,"$#.0"),"T"),_xlfn.CONCAT(TEXT(V28,"$#"),"B")) -> $236B | K28: =_xlfn.CONCAT(TEXT(SUMIFS(raw_output!$N$2:$N$197,raw_output!$M$2:$M$197,'Overall Output. Labeled'!$N28,raw_output!$A$2:$A$197,'Overall Output. Labeled'!$U28,raw_output!$B$2:$B$197,'Overall Output. Labeled'!$S28,raw_output!$C$2:$C$197,'Overall Output. Labeled'!$T28,raw_output!$D$2:$D$197,'Overall Output. Labeled'!$P28,raw_output!$E$2:$E$197,'Overall Output. Labeled'!$Q28,raw_output!$F$2:$F$197,'Overall Output. Labeled'!$R28),"$#.0"),"T") -> $9.9T | L28: =IF(W28>1000,_xlfn.CONCAT(TEXT(W28/1000,"#.#"),"M"),_xlfn.CONCAT(TEXT(W28,"#"),"k")) -> k | M28: =TEXT(SUMIFS(raw_output!$L$2:$L$197,raw_output!$M$2:$M$197,'Overall Output. Labeled'!$N28,raw_output!$A$2:$A$197,'Overall Output. Labeled'!$U28,raw_output!$B$2:$B$197,'Overall Output. Labeled'!$S28,raw_output!$C$2:$C$197,'Overall Output. Labeled'!$T28,raw_output!$D$2:$D$197,'Overall Output. Labeled'!$P28,raw_output!$E$2:$E$197,'Overall Output. Labeled'!$Q28,raw_output!$F$2:$F$197,'Overall Output. Labeled'!$R28),"$#.##") -> $818.1 | N28: 0.02 | O28: 1 | P28: =F28 -> 0 | Q28: 0.47 | R28: =H28 -> 0 | S28: 10 | T28: 20 | U28: 40 | V28: =SUMIFS(raw_output!$K$2:$K$197,raw_output!$A$2:$A$197,'Overall Output. Labeled'!$U28,raw_output!$B$2:$B$197,'Overall Output. Labeled'!$S28,raw_output!$C$2:$C$197,'Overall Output. Labeled'!$T28,raw_output!$D$2:$D$197,'Overall Output. Labeled'!$P28,raw_output!$E$2:$E$197,'Overall Output. Labeled'!$Q28,raw_output!$F$2:$F$197,'Overall Output. Labeled'!$R28,raw_output!$M$2:$M$197,'Overall Output. Labeled'!$N28) -> 235.76946 | W28: {=SUMIFS(raw_output!$J$2:$J$197,raw_output!$M$2:$M$197,'Overall Output. Labeled'!$N28,raw_output!$A$2:$A$197,'Overall Output. Labeled'!$U28,raw_output!$B$2:$B$197,'Overall Output. Labeled'!$S28,raw_output!$C$2:$C$197,'Overall Output. Labeled'!$T28,raw_output!$D$2:$D$197,'Overall Output. Labeled'!$P28,raw_output!$E$2:$E$197,'Overall Output. Labeled'!$Q28,raw_output!$F$2:$F$197,'Overall Output. Labeled'!$R28)*1000} -> 0
A29: Appendix | C29: 1% increase in fertility | I29: =CONCATENATE(U29,"+") -> 40+ | J29: =IF(V29>1000,_xlfn.CONCAT(TEXT(V29/1000,"$#.0"),"T"),_xlfn.CONCAT(TEXT(V29,"$#"),"B")) -> -$21B | K29: =_xlfn.CONCAT(TEXT(SUMIFS(raw_output!$N$2:$N$197,raw_output!$M$2:$M$197,'Overall Output. Labeled'!$N29,raw_output!$A$2:$A$197,'Overall Output. Labeled'!$U29,raw_output!$B$2:$B$197,'Overall Output. Labeled'!$S29,raw_output!$C$2:$C$197,'Overall Output. Labeled'!$T29,raw_output!$D$2:$D$197,'Overall Output. Labeled'!$P29,raw_output!$E$2:$E$197,'Overall Output. Labeled'!$Q29,raw_output!$F$2:$F$197,'Overall Output. Labeled'!$R29),"$#.0"),"T") -> $8.7T | L29: =IF(W29>1000,_xlfn.CONCAT(TEXT(W29/1000,"#.#"),"M"),_xlfn.CONCAT(TEXT(W29,"#"),"k")) -> 394k | M29: =TEXT(SUMIFS(raw_output!$L$2:$L$197,raw_output!$M$2:$M$197,'Overall Output. Labeled'!$N29,raw_output!$A$2:$A$197,'Overall Output. Labeled'!$U29,raw_output!$B$2:$B$197,'Overall Output. Labeled'!$S29,raw_output!$C$2:$C$197,'Overall Output. Labeled'!$T29,raw_output!$D$2:$D$197,'Overall Output. Labeled'!$P29,raw_output!$E$2:$E$197,'Overall Output. Labeled'!$Q29,raw_output!$F$2:$F$197,'Overall Output. Labeled'!$R29),"$#.##") -> -$91.44 | N29: 0.02 | O29: 1 | P29: =F29 -> 0 | Q29: =G29 -> 0 | R29: 0.54 | S29: 10 | T29: 20 | U29: 40 | V29: =SUMIFS(raw_output!$K$2:$K$197,raw_output!$A$2:$A$197,'Overall Output. Labeled'!$U29,raw_output!$B$2:$B$197,'Overall Output. Labeled'!$S29,raw_output!$C$2:$C$197,'Overall Output. Labeled'!$T29,raw_output!$D$2:$D$197,'Overall Output. Labeled'!$P29,raw_output!$E$2:$E$197,'Overall Output. Labeled'!$Q29,raw_output!$F$2:$F$197,'Overall Output. Labeled'!$R29,raw_output!$M$2:$M$197,'Overall Output. Labeled'!$N29) -> -20.851594 | W29: {=SUMIFS(raw_output!$J$2:$J$197,raw_output!$M$2:$M$197,'Overall Output. Labeled'!$N29,raw_output!$A$2:$A$197,'Overall Output. Labeled'!$U29,raw_output!$B$2:$B$197,'Overall Output. Labeled'!$S29,raw_output!$C$2:$C$197,'Overall Output. Labeled'!$T29,raw_output!$D$2:$D$197,'Overall Output. Labeled'!$P29,raw_output!$E$2:$E$197,'Overall Output. Labeled'!$Q29,raw_output!$F$2:$F$197,'Overall Output. Labeled'!$R29)*1000} -> 393.80424
A30: Appendix | C30: 1% increase in all 3 channels | I30: =CONCATENATE(U30,"+") -> 40+ | J30: =IF(V30>1000,_xlfn.CONCAT(TEXT(V30/1000,"$#.0"),"T"),_xlfn.CONCAT(TEXT(V30,"$#"),"B")) -> $274B | K30: =_xlfn.CONCAT(TEXT(SUMIFS(raw_output!$N$2:$N$197,raw_output!$M$2:$M$197,'Overall Output. Labeled'!$N30,raw_output!$A$2:$A$197,'Overall Output. Labeled'!$U30,raw_output!$B$2:$B$197,'Overall Output. Labeled'!$S30,raw_output!$C$2:$C$197,'Overall Output. Labeled'!$T30,raw_output!$D$2:$D$197,'Overall Output. Labeled'!$P30,raw_output!$E$2:$E$197,'Overall Output. Labeled'!$Q30,raw_output!$F$2:$F$197,'Overall Output. Labeled'!$R30),"$#.0"),"T") -> $21.0T | L30: =IF(W30>1000,_xlfn.CONCAT(TEXT(W30/1000,"#.#"),"M"),_xlfn.CONCAT(TEXT(W30,"#"),"k")) -> 743k | M30: =TEXT(SUMIFS(raw_output!$L$2:$L$197,raw_output!$M$2:$M$197,'Overall Output. Labeled'!$N30,raw_output!$A$2:$A$197,'Overall Output. Labeled'!$U30,raw_output!$B$2:$B$197,'Overall Output. Labeled'!$S30,raw_output!$C$2:$C$197,'Overall Output. Labeled'!$T30,raw_output!$D$2:$D$197,'Overall Output. Labeled'!$P30,raw_output!$E$2:$E$197,'Overall Output. Labeled'!$Q30,raw_output!$F$2:$F$197,'Overall Output. Labeled'!$R30),"$#.##") -> $681.02 | N30: 0.02 | O30: 1 | P30: 0.13 | Q30: 0.47 | R30: 0.54 | S30: 10 | T30: 20 | U30: 40 | V30: =SUMIFS(raw_output!$K$2:$K$197,raw_output!$A$2:$A$197,'Overall Output. Labeled'!$U30,raw_output!$B$2:$B$197,'Overall Output. Labeled'!$S30,raw_output!$C$2:$C$197,'Overall Output. Labeled'!$T30,raw_output!$D$2:$D$197,'Overall Output. Labeled'!$P30,raw_output!$E$2:$E$197,'Overall Output. Labeled'!$Q30,raw_output!$F$2:$F$197,'Overall Output. Labeled'!$R30,raw_output!$M$2:$M$197,'Overall Output. Labeled'!$N30) -> 274.0875 | W30: {=SUMIFS(raw_output!$J$2:$J$197,raw_output!$M$2:$M$197,'Overall Output. Labeled'!$N30,raw_output!$A$2:$A$197,'Overall Output. Labeled'!$U30,raw_output!$B$2:$B$197,'Overall Output. Labeled'!$S30,raw_output!$C$2:$C$197,'Overall Output. Labeled'!$T30,raw_output!$D$2:$D$197,'Overall Output. Labeled'!$P30,raw_output!$E$2:$E$197,'Overall Output. Labeled'!$Q30,raw_output!$F$2:$F$197,'Overall Output. Labeled'!$R30)*1000} -> 742.72155
A31: Appendix | C31: 41 is the new 40, 1% discount | F31: 1 | G31: 1 | H31: 1 | I31: =CONCATENATE(U31,"+") -> 40+ | J31: =IF(V31>1000,_xlfn.CONCAT(TEXT(V31/1000,"$#.0"),"T"),_xlfn.CONCAT(TEXT(V31,"$#"),"B")) -> $408B | K31: =_xlfn.CONCAT(TEXT(SUMIFS(raw_output!$N$2:$N$197,raw_output!$M$2:$M$197,'Overall Output. Labeled'!$N31,raw_output!$A$2:$A$197,'Overall Output. Labeled'!$U31,raw_output!$B$2:$B$197,'Overall Output. Labeled'!$S31,raw_output!$C$2:$C$197,'Overall Output. Labeled'!$T31,raw_output!$D$2:$D$197,'Overall Output. Labeled'!$P31,raw_output!$E$2:$E$197,'Overall Output. Labeled'!$Q31,raw_output!$F$2:$F$197,'Overall Output. Labeled'!$R31),"$#.0"),"T") -> $53.3T | L31: =IF(W31>1000,_xlfn.CONCAT(TEXT(W31/1000,"#.#"),"M"),_xlfn.CONCAT(TEXT(W31,"#"),"k")) -> 1.7M | M31: =TEXT(SUMIFS(raw_output!$L$2:$L$197,raw_output!$M$2:$M$197,'Overall Output. Labeled'!$N31,raw_output!$A$2:$A$197,'Overall Output. Labeled'!$U31,raw_output!$B$2:$B$197,'Overall Output. Labeled'!$S31,raw_output!$C$2:$C$197,'Overall Output. Labeled'!$T31,raw_output!$D$2:$D$197,'Overall Output. Labeled'!$P31,raw_output!$E$2:$E$197,'Overall Output. Labeled'!$Q31,raw_output!$F$2:$F$197,'Overall Output. Labeled'!$R31),"$#.##") -> $425.39 | N31: 0.01 | O31: 0.5 | P31: =F31*$O31 -> 0.5 | Q31: =G31*$O31 -> 0.5 | R31: =H31*$O31 -> 0.5 | S31: 10 | T31: 20 | U31: 40 | V31: =SUMIFS(raw_output!$K$2:$K$197,raw_output!$A$2:$A$197,'Overall Output. Labeled'!$U31,raw_output!$B$2:$B$197,'Overall Output. Labeled'!$S31,raw_output!$C$2:$C$197,'Overall Output. Labeled'!$T31,raw_output!$D$2:$D$197,'Overall Output. Labeled'!$P31,raw_output!$E$2:$E$197,'Overall Output. Labeled'!$Q31,raw_output!$F$2:$F$197,'Overall Output. Labeled'!$R31,raw_output!$M$2:$M$197,'Overall Output. Labeled'!$N31) -> 408.38262 | W31: {=SUMIFS(raw_output!$J$2:$J$197,raw_output!$M$2:$M$197,'Overall Output. Labeled'!$N31,raw_output!$A$2:$A$197,'Overall Output. Labeled'!$U31,raw_output!$B$2:$B$197,'Overall Output. Labeled'!$S31,raw_output!$C$2:$C$197,'Overall Output. Labeled'!$T31,raw_output!$D$2:$D$197,'Overall Output. Labeled'!$P31,raw_output!$E$2:$E$197,'Overall Output. Labeled'!$Q31,raw_output!$F$2:$F$197,'Overall Output. Labeled'!$R31)*1000} -> 1723.1995
